Workbook

Sheet Cap Table
A1: Capitalization Table
A2: Share Price | B2: =Valuation!B6 -> 472.89
A3: Shares Outstanding Build
A4: Basic Shares Outstanding | B4: =SUM(B5:B6) -> 205.5842
A5: Issued ordinary shares | B5: 210.24127
A6: (–) Treasury shares | B6: -4.657063
A7: RSUs | B7: 1.456016
A8: Option Build
A9: Options | B9: 4.496814
A10: Average Option Strike Price | B10: 256.44
A11: Net New Shares Created by Options | B11: =MAX(0,B9*(B2-B10)/B2) -> 2.0582702
A12: Total Diluted Shares Outstanding | B12: =B4+B7+B11 -> 209.09849
A13: Market Cap (in Millions) | B13: =B2*B12 -> 98880.585
A14: (+) Debt | B14: =(Model!O50+Model!O60)*Valuation!B7 -> 0
A15: (–) Cash & Short-Term Investments | B15: =(Model!O39+Model!O40)*Valuation!B7 -> 10569.949
A16: Enterprise Value | B16: =B13+B14-B15 -> 88310.636
A17: LTM EV / Sales | B17: =B16/(SUM(Model!L5:O5)*Valuation!B7) -> 4.3303481
A18: LTM EV / EBITDA | B18: =B16/((SUM(Model!L13:O13)+SUM(Model!L71:O71)+SUM(Model!L72:O72))*Valuation!B7) -> 28.449617

Sheet Model
A1: SPOT Quarterly Three-Statement Model (€m, except per-share data and shares)
A2: Period | B2: Q1-2023 | C2: Q2-2023 | D2: Q3-2023 | E2: Q4-2023 | F2: Q1-2024 | G2: Q2-2024 | H2: Q3-2024 | I2: Q4-2024 | J2: Q1-2025 | K2: Q2-2025 | L2: Q3-2025 | M2: Q4-2025 | N2: Q1-2026 | O2: Q2-2026 | P2: Q3-2026E | Q2: Q4-2026E | R2: Q1-2027E | S2: Q2-2027E | U2: FY2023 | V2: FY2024 | W2: FY2025 | X2: FY2026E | Y2: NTM Q2-27
A4: Income Statement
A5: Revenue | B5: 3042 | C5: 3177 | D5: 3357 | E5: ='Raw Numbers'!$B$4-SUM(B5:D5) -> 3671 | F5: 3636 | G5: 3807 | H5: 3988 | I5: ='Raw Numbers'!$C$4-SUM(F5:H5) -> 4242 | J5: 4190 | K5: 4193 | L5: 4272 | M5: ='Raw Numbers'!$D$4-SUM(J5:L5) -> 4531 | N5: 4533 | O5: 4777 | P5: =Assumptions!B4 -> 5000 | Q5: =M5*(1+Assumptions!C5) -> 5029.41 | R5: =N5*(1+Assumptions!D5) -> 4986.3 | S5: =O5*(1+Assumptions!E5) -> 5254.7 | U5: =SUM(B5,C5,D5,E5) -> 13247 | V5: =SUM(F5,G5,H5,I5) -> 15673 | W5: =SUM(J5,K5,L5,M5) -> 17186 | X5: =SUM(N5,O5,P5,Q5) -> 19339.41 | Y5: =SUM(P5,Q5,R5,S5) -> 20270.41
A6: Cost of revenue | B6: 2276 | C6: 2411 | D6: 2472 | E6: ='Raw Numbers'!$B$5-SUM(B6:D6) -> 2691 | F6: 2632 | G6: 2695 | H6: 2748 | I6: ='Raw Numbers'!$C$5-SUM(F6:H6) -> 2874 | J6: 2864 | K6: 2873 | L6: 2921 | M6: ='Raw Numbers'!$D$5-SUM(J6:L6) -> 3032 | N6: 3038 | O6: 3181 | P6: =P5-P7 -> 3355 | Q6: =Q5-Q7 -> 3384.7929 | R6: =R5-R7 -> 3350.7936 | S6: =S5-S7 -> 3525.9037 | U6: =SUM(B6,C6,D6,E6) -> 9850 | V6: =SUM(F6,G6,H6,I6) -> 10949 | W6: =SUM(J6,K6,L6,M6) -> 11690 | X6: =SUM(N6,O6,P6,Q6) -> 12958.793 | Y6: =SUM(P6,Q6,R6,S6) -> 13616.49
A7: Gross profit | B7: =B5-B6 -> 766 | C7: =C5-C6 -> 766 | D7: =D5-D6 -> 885 | E7: =E5-E6 -> 980 | F7: =F5-F6 -> 1004 | G7: =G5-G6 -> 1112 | H7: =H5-H6 -> 1240 | I7: =I5-I6 -> 1368 | ... O7: =O5-O6 -> 1596 | P7: =P5*Assumptions!B6 -> 1645 | Q7: =Q5*Assumptions!C6 -> 1644.6171 | R7: =R5*Assumptions!D6 -> 1635.5064 | S7: =S5*Assumptions!E6 -> 1728.7963 | U7: =SUM(B7,C7,D7,E7) -> 3397 | V7: =SUM(F7,G7,H7,I7) -> 4724 | W7: =SUM(J7,K7,L7,M7) -> 5496 | X7: =SUM(N7,O7,P7,Q7) -> 6380.6171 | Y7: =SUM(P7,Q7,R7,S7) -> 6653.9198
A8: Gross margin | B8: =B7/B5 -> 0.25180802 | C8: =C7/C5 -> 0.24110796 | D8: =D7/D5 -> 0.26362824 | E8: =E7/E5 -> 0.26695723 | F8: =F7/F5 -> 0.27612761 | G8: =G7/G5 -> 0.29209351 | H8: =H7/H5 -> 0.3109328 | I8: =I7/I5 -> 0.32248939 | ... S8: =S7/S5 -> 0.329 | U8: =U7/U5 -> 0.25643542 | V8: =V7/V5 -> 0.30141007 | W8: =W7/W5 -> 0.31979518 | X8: =X7/X5 -> 0.32992822 | Y8: =Y7/Y5 -> 0.32825778
A9: Research and development | B9: 435 | C9: 453 | D9: 369 | E9: ='Raw Numbers'!$B$7-SUM(B9:D9) -> 468 | F9: 389 | G9: 379 | H9: 342 | I9: ='Raw Numbers'!$C$7-SUM(F9:H9) -> 376 | J9: 379 | K9: 415 | L9: 309 | M9: ='Raw Numbers'!$D$7-SUM(J9:L9) -> 290 | N9: 331 | O9: 403 | P9: =(P7-Assumptions!B7)*Assumptions!B8 -> 409.5 | Q9: =Q5*Assumptions!C11 -> 377.20575 | R9: =R5*Assumptions!D11 -> 378.9588 | S9: =S5*Assumptions!E11 -> 409.8666 | U9: =SUM(B9,C9,D9,E9) -> 1725 | V9: =SUM(F9,G9,H9,I9) -> 1486 | W9: =SUM(J9,K9,L9,M9) -> 1393 | X9: =SUM(N9,O9,P9,Q9) -> 1520.7058 | Y9: =SUM(P9,Q9,R9,S9) -> 1575.5312
A10: Sales and marketing | B10: 347 | C10: 399 | D10: 355 | E10: ='Raw Numbers'!$B$8-SUM(B10:D10) -> 432 | F10: 324 | G10: 343 | H10: 332 | I10: ='Raw Numbers'!$C$8-SUM(F10:H10) -> 393 | J10: 314 | K10: 364 | L10: 349 | M10: ='Raw Numbers'!$D$8-SUM(J10:L10) -> 399 | N10: 342 | O10: 390 | P10: =(P7-Assumptions!B7)*Assumptions!B9 -> 409.5 | Q10: =Q5*Assumptions!C12 -> 402.3528 | R10: =R5*Assumptions!D12 -> 398.904 | S10: =S5*Assumptions!E12 -> 420.376 | U10: =SUM(B10,C10,D10,E10) -> 1533 | V10: =SUM(F10,G10,H10,I10) -> 1392 | W10: =SUM(J10,K10,L10,M10) -> 1426 | X10: =SUM(N10,O10,P10,Q10) -> 1543.8528 | Y10: =SUM(P10,Q10,R10,S10) -> 1631.1328
A11: General and administrative | B11: 140 | C11: 161 | D11: 129 | E11: ='Raw Numbers'!$B$9-SUM(B11:D11) -> 155 | F11: 123 | G11: 124 | H11: 112 | I11: ='Raw Numbers'!$C$9-SUM(F11:H11) -> 122 | J11: 124 | K11: 135 | L11: 111 | M11: ='Raw Numbers'!$D$9-SUM(J11:L11) -> 109 | N11: 107 | O11: 148 | P11: =(P7-Assumptions!B7)*Assumptions!B10 -> 156 | Q11: =Q5*Assumptions!C13 -> 130.76466 | R11: =R5*Assumptions!D13 -> 129.6438 | S11: =S5*Assumptions!E13 -> 141.8769 | U11: =SUM(B11,C11,D11,E11) -> 585 | V11: =SUM(F11,G11,H11,I11) -> 481 | W11: =SUM(J11,K11,L11,M11) -> 479 | X11: =SUM(N11,O11,P11,Q11) -> 541.76466 | Y11: =SUM(P11,Q11,R11,S11) -> 558.28536
A12: Total operating expenses | B12: =SUM(B9:B11) -> 922 | C12: =SUM(C9:C11) -> 1013 | D12: =SUM(D9:D11) -> 853 | E12: =SUM(E9:E11) -> 1055 | F12: =SUM(F9:F11) -> 836 | G12: =SUM(G9:G11) -> 846 | H12: =SUM(H9:H11) -> 786 | I12: =SUM(I9:I11) -> 891 | ... S12: =SUM(S9:S11) -> 972.1195 | U12: =SUM(B12,C12,D12,E12) -> 3843 | V12: =SUM(F12,G12,H12,I12) -> 3359 | W12: =SUM(J12,K12,L12,M12) -> 3298 | X12: =SUM(N12,O12,P12,Q12) -> 3606.3232 | Y12: =SUM(P12,Q12,R12,S12) -> 3764.9493
A13: Operating income/(loss) | B13: =B7-B12 -> -156 | C13: =C7-C12 -> -247 | D13: =D7-D12 -> 32 | E13: =E7-E12 -> -75 | F13: =F7-F12 -> 168 | G13: =G7-G12 -> 266 | H13: =H7-H12 -> 454 | I13: =I7-I12 -> 477 | ... S13: =S7-S12 -> 756.6768 | U13: =SUM(B13,C13,D13,E13) -> -446 | V13: =SUM(F13,G13,H13,I13) -> 1365 | W13: =SUM(J13,K13,L13,M13) -> 2198 | X13: =SUM(N13,O13,P13,Q13) -> 2774.2939 | Y13: =SUM(P13,Q13,R13,S13) -> 2888.9705
A14: Operating margin | B14: =B13/B5 -> -0.051282051 | C14: =C13/C5 -> -0.077746302 | D14: =D13/D5 -> 0.0095323205 | E14: =E13/E5 -> -0.0204304 | F14: =F13/F5 -> 0.04620462 | G14: =G13/G5 -> 0.06987129 | H14: =H13/H5 -> 0.11384152 | I14: =I13/I5 -> 0.11244696 | ... S14: =S13/S5 -> 0.144 | U14: =U13/U5 -> -0.033668 | V14: =V13/V5 -> 0.087092452 | W14: =W13/W5 -> 0.1278948 | X14: =X13/X5 -> 0.14345287 | Y14: =Y13/Y5 -> 0.14252156
A15: Finance income | B15: 27 | C15: 33 | D15: 55 | E15: ='Raw Numbers'!$B$12-SUM(B15:D15) -> 46 | F15: 59 | G15: 76 | H15: 66 | I15: ='Raw Numbers'!$C$12-SUM(F15:H15) -> 127 | J15: 71 | K15: 89 | L15: 262 | M15: ='Raw Numbers'!$D$12-SUM(J15:L15) -> -130 | N15: 248 | O15: 86 | P15: =(O40+O39)*Assumptions!B14/4 -> 82.145 | Q15: =(P40+P39)*Assumptions!C14/4 -> 86.825352 | R15: =(Q40+Q39)*Assumptions!D14/4 -> 90.442361 | S15: =(R40+R39)*Assumptions!E14/4 -> 93.479336 | U15: =SUM(B15,C15,D15,E15) -> 161 | V15: =SUM(F15,G15,H15,I15) -> 328 | W15: =SUM(J15,K15,L15,M15) -> 292 | X15: =SUM(N15,O15,P15,Q15) -> 502.97035 | Y15: =SUM(P15,Q15,R15,S15) -> 352.89205
A16: Finance costs | B16: -77 | C16: -27 | D16: -14 | E16: ='Raw Numbers'!$B$13-SUM(B16:D16) -> -102 | F16: -53 | G16: -72 | H16: -122 | I16: ='Raw Numbers'!$C$13-SUM(F16:H16) -> -105 | J16: -252 | K16: -447 | L16: -17 | M16: ='Raw Numbers'!$D$13-SUM(J16:L16) -> 450 | N16: -26 | O16: -21 | P16: =-P5*Assumptions!B15 -> -22.5 | Q16: =-Q5*Assumptions!C15 -> -22.632345 | R16: =-R5*Assumptions!D15 -> -22.43835 | S16: =-S5*Assumptions!E15 -> -23.64615 | U16: =SUM(B16,C16,D16,E16) -> -220 | V16: =SUM(F16,G16,H16,I16) -> -352 | W16: =SUM(J16,K16,L16,M16) -> -266 | X16: =SUM(N16,O16,P16,Q16) -> -92.132345 | Y16: =SUM(P16,Q16,R16,S16) -> -91.216845
A17: Finance income/(costs) - net | B17: =SUM(B15:B16) -> -50 | C17: =SUM(C15:C16) -> 6 | D17: =SUM(D15:D16) -> 41 | E17: =SUM(E15:E16) -> -56 | F17: =SUM(F15:F16) -> 6 | G17: =SUM(G15:G16) -> 4 | H17: =SUM(H15:H16) -> -56 | I17: =SUM(I15:I16) -> 22 | ... S17: =SUM(S15:S16) -> 69.833186 | U17: =SUM(B17,C17,D17,E17) -> -59 | V17: =SUM(F17,G17,H17,I17) -> -24 | W17: =SUM(J17,K17,L17,M17) -> 26 | X17: =SUM(N17,O17,P17,Q17) -> 410.83801 | Y17: =SUM(P17,Q17,R17,S17) -> 261.6752
A18: Income/(loss) before tax | B18: =B13+B17 -> -206 | C18: =C13+C17 -> -241 | D18: =D13+D17 -> 73 | E18: =E13+E17 -> -131 | F18: =F13+F17 -> 174 | G18: =G13+G17 -> 270 | H18: =H13+H17 -> 398 | I18: =I13+I17 -> 499 | ... S18: =S13+S17 -> 826.50999 | U18: =SUM(B18,C18,D18,E18) -> -505 | V18: =SUM(F18,G18,H18,I18) -> 1341 | W18: =SUM(J18,K18,L18,M18) -> 2224 | X18: =SUM(N18,O18,P18,Q18) -> 3185.1319 | Y18: =SUM(P18,Q18,R18,S18) -> 3150.6457
A19: Income tax expense/(benefit) | B19: 19 | C19: 61 | D19: 8 | E19: ='Raw Numbers'!$B$16-SUM(B19:D19) -> -61 | F19: -23 | G19: -4 | H19: 98 | I19: ='Raw Numbers'!$C$16-SUM(F19:H19) -> 132 | J19: 103 | K19: 134 | L19: -72 | M19: ='Raw Numbers'!$D$16-SUM(J19:L19) -> -153 | N19: 216 | O19: 175 | P19: =MAX(0,P18*Assumptions!B16) -> 175.1148 | Q19: =MAX(0,Q18*Assumptions!C16) -> 191.63685 | R19: =MAX(0,R18*Assumptions!D16) -> 191.04091 | S19: =MAX(0,S18*Assumptions!E16) -> 198.3624 | U19: =SUM(B19,C19,D19,E19) -> 27 | V19: =SUM(F19,G19,H19,I19) -> 203 | W19: =SUM(J19,K19,L19,M19) -> 12 | X19: =SUM(N19,O19,P19,Q19) -> 757.75165 | Y19: =SUM(P19,Q19,R19,S19) -> 756.15496
A20: Net income/(loss) | B20: =B18-B19 -> -225 | C20: =C18-C19 -> -302 | D20: =D18-D19 -> 65 | E20: =E18-E19 -> -70 | F20: =F18-F19 -> 197 | G20: =G18-G19 -> 274 | H20: =H18-H19 -> 300 | I20: =I18-I19 -> 367 | ... S20: =S18-S19 -> 628.14759 | U20: =SUM(B20,C20,D20,E20) -> -532 | V20: =SUM(F20,G20,H20,I20) -> 1138 | W20: =SUM(J20,K20,L20,M20) -> 2212 | X20: =SUM(N20,O20,P20,Q20) -> 2427.3802 | Y20: =SUM(P20,Q20,R20,S20) -> 2394.4907
A21: Basic EPS | B21: -1.16 | C21: -1.55 | D21: 0.33 | E21: =E20/E23 -> -0.35702463 | F21: 0.99 | G21: 1.37 | H21: 1.49 | I21: =I20/I23 -> 1.8085065 | J21: 1.1 | K21: -0.42 | L21: 4.36 | M21: =M20/M23 -> 5.7047789 | N21: 3.5 | O21: 2.65 | P21: =P20/P23 -> 2.6946642 | Q21: =Q20/Q23 -> 2.9489052 | R21: =R20/R23 -> 2.939735 | S21: =S20/S23 -> 3.0523979 | U21: ='Raw Numbers'!$B$18 -> -2.73 | V21: ='Raw Numbers'!$C$18 -> 5.67 | W21: ='Raw Numbers'!$D$18 -> 10.77 | X21: =X20/X23 -> 11.796547 | Y21: =Y20/Y23 -> 11.635702
A22: Diluted EPS | B22: -1.16 | C22: -1.55 | D22: 0.33 | E22: =IF(E20<0,E21,E20/E24) -> -0.35702463 | F22: 0.97 | G22: 1.33 | H22: 1.45 | I22: =IF(I20<0,I21,I20/I24) -> 1.7420686 | J22: 1.07 | K22: -0.42 | L22: 3.28 | M22: =IF(M20<0,M21,M20/M24) -> 5.5227182 | N22: 3.45 | O22: 2.61 | P22: =P20/P24 -> 2.6546741 | Q22: =Q20/Q24 -> 2.9051421 | R22: =R20/R24 -> 2.896108 | S22: =S20/S24 -> 3.0070988 | U22: ='Raw Numbers'!$B$19 -> -2.73 | V22: ='Raw Numbers'!$C$19 -> 5.5 | W22: ='Raw Numbers'!$D$19 -> 10.51 | X22: =X20/X24 -> 11.615435 | Y22: =Y20/Y24 -> 11.463023
A23: Weighted-average basic shares | B23: 193.56246 | C23: 194.42013 | D23: 194.88172 | E23: =4*'Raw Numbers'!$B$20-SUM(B23:D23) -> 196.0649 | F23: 198.02546 | G23: 199.95917 | H23: 201.57557 | I23: =4*'Raw Numbers'!$C$20-SUM(F23:H23) -> 202.92988 | J23: 204.46793 | K23: 205.427 | L23: 205.9645 | M23: =4*'Raw Numbers'!$D$20-SUM(J23:L23) -> 205.79237 | N23: 205.71685 | O23: 205.78824 | P23: =O23+Assumptions!B17 -> 205.78824 | Q23: =P23+Assumptions!C17 -> 205.78824 | R23: =Q23+Assumptions!D17 -> 205.78824 | S23: =R23+Assumptions!E17 -> 205.78824 | U23: ='Raw Numbers'!$B$20 -> 194.7323 | V23: ='Raw Numbers'!$C$20 -> 200.62252 | W23: ='Raw Numbers'!$D$20 -> 205.41295 | X23: =AVERAGE(N23,O23,P23,Q23) -> 205.77039 | Y23: =AVERAGE(P23,Q23,R23,S23) -> 205.78824
A24: Weighted-average diluted shares | B24: 193.56246 | C24: 194.42013 | D24: 198.01237 | E24: =E23 -> 196.0649 | F24: 203.77304 | G24: 206.11985 | H24: 207.3995 | I24: =4*'Raw Numbers'!$C$21-SUM(F24:H24) -> 210.66908 | J24: 210.24348 | K24: 205.427 | L24: 213.78974 | M24: =4*'Raw Numbers'!$D$21-SUM(J24:L24) -> 212.57648 | N24: 209.28045 | O24: 208.85847 | P24: =P23+Assumptions!B18 -> 208.88824 | Q24: =Q23+Assumptions!C18 -> 208.88824 | R24: =R23+Assumptions!D18 -> 208.88824 | S24: =S23+Assumptions!E18 -> 208.88824 | U24: ='Raw Numbers'!$B$21 -> 194.7323 | V24: ='Raw Numbers'!$C$21 -> 206.99037 | W24: ='Raw Numbers'!$D$21 -> 210.50917 | X24: =AVERAGE(N24,O24,P24,Q24) -> 208.97885 | Y24: =AVERAGE(P24,Q24,R24,S24) -> 208.88824
A27: Balance Sheet
A28: Lease right-of-use assets | B28: 413 | C28: 344 | D28: 343 | E28: 300 | F28: 274 | G28: 254 | H28: 235 | I28: 226 | J28: 223 | K28: 256 | L28: 242 | M28: 234 | N28: 227 | O28: 225 | P28: =O28*(1+Assumptions!B29) -> 222.75 | Q28: =P28*(1+Assumptions!C29) -> 220.5225 | R28: =Q28*(1+Assumptions!D29) -> 218.31727 | S28: =R28*(1+Assumptions!E29) -> 216.1341 | U28: =E28 -> 300 | V28: =I28 -> 226 | W28: =M28 -> 234 | X28: =Q28 -> 220.5225 | Y28: =S28 -> 216.1341
A29: Property & equipment | B29: 331 | C29: 280 | D29: 275 | E29: 247 | F29: 224 | G29: 211 | H29: 195 | I29: 188 | J29: 178 | K29: 161 | L29: 174 | M29: 188 | N29: 182 | O29: 193 | P29: =MAX(0,O29-P71*0.45-P90) -> 209.25 | Q29: =MAX(0,P29-Q71*0.45-Q90) -> 225.59558 | R29: =MAX(0,Q29-R71*0.45-R90) -> 241.80106 | S29: =MAX(0,R29-S71*0.45-S90) -> 258.87883 | U29: =E29 -> 247 | V29: =I29 -> 188 | W29: =M29 -> 188 | X29: =Q29 -> 225.59558 | Y29: =S29 -> 258.87883
A30: Goodwill | B30: 1155 | C30: 1148 | D30: 1180 | E30: 1137 | F30: 1159 | G30: 1167 | H30: 1128 | I30: 1201 | J30: 1156 | K30: 1074 | L30: 1078 | M30: 1083 | N30: 1099 | O30: 1110 | P30: =O30 -> 1110 | Q30: =P30 -> 1110 | R30: =Q30 -> 1110 | S30: =R30 -> 1110 | U30: =E30 -> 1137 | V30: =I30 -> 1201 | W30: =M30 -> 1083 | X30: =Q30 -> 1110 | Y30: =S30 -> 1110
A31: Intangible assets | B31: 115 | C31: 105 | D31: 98 | E31: 84 | F31: 76 | G31: 68 | H31: 58 | I31: 48 | J31: 43 | K31: 37 | L31: 33 | M31: 41 | N31: 41 | O31: 36 | P31: =MAX(0,O31-P72) -> 31 | Q31: =MAX(0,P31-Q72) -> 25.97059 | R31: =MAX(0,Q31-R72) -> 20.98429 | S31: =MAX(0,R31-S72) -> 15.72959 | U31: =E31 -> 84 | V31: =I31 -> 48 | W31: =M31 -> 41 | X31: =Q31 -> 25.97059 | Y31: =S31 -> 15.72959
A32: Long-term investments | B32: 1134 | C32: 1015 | D32: 903 | E32: 1215 | F32: 1534 | G32: 1931 | H32: 1604 | I32: 1635 | J32: 1958 | K32: 2417 | L32: 2888 | M32: 2181 | N32: 1194 | O32: 1118 | P32: =O32 -> 1118 | Q32: =P32 -> 1118 | R32: =Q32 -> 1118 | S32: =R32 -> 1118 | U32: =E32 -> 1215 | V32: =I32 -> 1635 | W32: =M32 -> 2181 | X32: =Q32 -> 1118 | Y32: =S32 -> 1118
A33: Restricted cash & other non-current assets | B33: 77 | C33: 76 | D33: 75 | E33: 75 | F33: 72 | G33: 70 | H33: 72 | I33: 68 | J33: 65 | K33: 59 | L33: 61 | M33: 61 | N33: 59 | O33: 56 | P33: =O33 -> 56 | Q33: =P33 -> 56 | R33: =Q33 -> 56 | S33: =R33 -> 56 | U33: =E33 -> 75 | V33: =I33 -> 68 | W33: =M33 -> 61 | X33: =Q33 -> 56 | Y33: =S33 -> 56
A34: Finance lease receivables | B34: 0 | C34: 0 | D34: 0 | E34: 0 | F34: 51 | G34: 52 | H34: 64 | I34: 74 | J34: 74 | K34: 68 | L34: 69 | M34: 69 | N34: 71 | O34: 71 | P34: =O34 -> 71 | Q34: =P34 -> 71 | R34: =Q34 -> 71 | S34: =R34 -> 71 | U34: =E34 -> 0 | V34: =I34 -> 74 | W34: =M34 -> 69 | X34: =Q34 -> 71 | Y34: =S34 -> 71
A35: Deferred tax assets | B35: 11 | C35: 15 | D35: 23 | E35: 28 | F35: 41 | G35: 49 | H35: 194 | I35: 186 | J35: 136 | K35: 94 | L35: 87 | M35: 662 | N35: 596 | O35: 563 | P35: =O35 -> 563 | Q35: =P35 -> 563 | R35: =Q35 -> 563 | S35: =R35 -> 563 | U35: =E35 -> 28 | V35: =I35 -> 186 | W35: =M35 -> 662 | X35: =Q35 -> 563 | Y35: =S35 -> 563
A36: Total non-current assets | B36: =SUM(B28:B35) -> 3236 | C36: =SUM(C28:C35) -> 2983 | D36: =SUM(D28:D35) -> 2897 | E36: =SUM(E28:E35) -> 3086 | F36: =SUM(F28:F35) -> 3431 | G36: =SUM(G28:G35) -> 3802 | H36: =SUM(H28:H35) -> 3550 | I36: =SUM(I28:I35) -> 3626 | ... S36: =SUM(S28:S35) -> 3408.7425 | U36: =E36 -> 3086 | V36: =I36 -> 3626 | W36: =M36 -> 4519 | X36: =Q36 -> 3390.0887 | Y36: =S36 -> 3408.7425
A37: Trade & other receivables | B37: 555 | C37: 632 | D37: 747 | E37: 858 | F37: 777 | G37: 753 | H37: 749 | I37: 771 | J37: 749 | K37: 736 | L37: 735 | M37: 802 | N37: 683 | O37: 780 | P37: =P5*Assumptions!B30 -> 815 | Q37: =Q5*Assumptions!C30 -> 819.79383 | R37: =R5*Assumptions!D30 -> 812.7669 | S37: =S5*Assumptions!E30 -> 856.5161 | U37: =E37 -> 858 | V37: =I37 -> 771 | W37: =M37 -> 802 | X37: =Q37 -> 819.79383 | Y37: =S37 -> 856.5161
A38: Income tax receivable | B38: 5 | C38: 8 | D38: 8 | E38: 20 | F38: 21 | G38: 35 | H38: 27 | I38: 28 | J38: 46 | K38: 83 | L38: 117 | M38: 116 | N38: 94 | O38: 92 | P38: =O38 -> 92 | Q38: =P38 -> 92 | R38: =Q38 -> 92 | S38: =R38 -> 92 | U38: =E38 -> 20 | V38: =I38 -> 28 | W38: =M38 -> 116 | X38: =Q38 -> 92 | Y38: =S38 -> 92
A39: Short-term investments | B39: 995 | C39: 866 | D39: 1097 | E39: 1100 | F39: 1220 | G39: 1344 | H39: 1392 | I39: 2667 | J39: 2894 | K39: 3183 | L39: 3606 | M39: 4209 | N39: 3491 | O39: 3450 | P39: =O39 -> 3450 | Q39: =P39 -> 3450 | R39: =Q39 -> 3450 | S39: =R39 -> 3450 | U39: =E39 -> 1100 | V39: =I39 -> 2667 | W39: =M39 -> 4209 | X39: =Q39 -> 3450 | Y39: =S39 -> 3450
A40: Cash & cash equivalents | B40: 2443 | C40: 2550 | D40: 2618 | E40: 3114 | F40: 3451 | G40: 4054 | H40: 4688 | I40: 4781 | J40: 5019 | K40: 5161 | L40: 5456 | M40: 5258 | N40: 5255 | O40: 5938 | P40: =P107 -> 6472.8974 | Q40: =Q107 -> 6886.2698 | R40: =R107 -> 7233.3527 | S40: =S107 -> 7854.0456 | U40: =E40 -> 3114 | V40: =I40 -> 4781 | W40: =M40 -> 5258 | X40: =Q40 -> 6886.2698 | Y40: =S40 -> 7854.0456
A41: Other current assets | B41: 295 | C41: 273 | D41: 225 | E41: 168 | F41: 175 | G41: 158 | H41: 147 | I41: 132 | J41: 146 | K41: 136 | L41: 143 | M41: 111 | N41: 136 | O41: 116 | P41: =P5*Assumptions!B31 -> 125 | Q41: =Q5*Assumptions!C31 -> 125.73525 | R41: =R5*Assumptions!D31 -> 124.6575 | S41: =S5*Assumptions!E31 -> 131.3675 | U41: =E41 -> 168 | V41: =I41 -> 132 | W41: =M41 -> 111 | X41: =Q41 -> 125.73525 | Y41: =S41 -> 131.3675
A42: Total current assets | B42: =SUM(B37:B41) -> 4293 | C42: =SUM(C37:C41) -> 4329 | D42: =SUM(D37:D41) -> 4695 | E42: =SUM(E37:E41) -> 5260 | F42: =SUM(F37:F41) -> 5644 | G42: =SUM(G37:G41) -> 6344 | H42: =SUM(H37:H41) -> 7003 | I42: =SUM(I37:I41) -> 8379 | ... S42: =SUM(S37:S41) -> 12383.929 | U42: =E42 -> 5260 | V42: =I42 -> 8379 | W42: =M42 -> 10496 | X42: =Q42 -> 11373.799 | Y42: =S42 -> 12383.929
A43: Total assets | B43: =B36+B42 -> 7529 | C43: =C36+C42 -> 7312 | D43: =D36+D42 -> 7592 | E43: =E36+E42 -> 8346 | F43: =F36+F42 -> 9075 | G43: =G36+G42 -> 10146 | H43: =H36+H42 -> 10553 | I43: =I36+I42 -> 12005 | ... S43: =S36+S42 -> 15792.672 | U43: =E43 -> 8346 | V43: =I43 -> 12005 | W43: =M43 -> 15015 | X43: =Q43 -> 14763.888 | Y43: =S43 -> 15792.672
...

Sheet Trading Comps
A1: Spotify Trading Comps & Multiple Reclassification
A3: Valuation Date | B3: Current SPOT Price ($) | C3: EUR / USD | D3: Current SPOT 2027E EV / EBITDA
A4: 2026-10-02 | B4: 472.89 | C4: 1.1259 | D4: 20.5
A7: Company | B7: Ticker | C7: Business model | D7: Currency | E7: 2025A Revenue | F7: 2026E Revenue | G7: 2027E Revenue | H7: 2026E Rev Growth | I7: 2027E Rev Growth | J7: 2026E EBITDA | K7: 2027E EBITDA | L7: 2026E EBITDA Margin | M7: 2027E EBITDA Margin | N7: 2026E EV / Revenue | O7: 2027E EV / Revenue | P7: 2026E EV / EBITDA | Q7: 2027E EV / EBITDA | R7: 2027E P/E
A8: Spotify Technology | B8: SPOT | C8: Global audio streaming platform | D8: EUR | E8: 17186 | F8: 19537 | G8: 22357 | H8: =F8/E8-1 -> 0.13679739 | I8: =G8/F8-1 -> 0.14434151 | J8: 2989 | K8: 3827 | L8: =J8/F8 -> 0.15299176 | M8: =K8/G8 -> 0.17117681 | N8: 4.18 | O8: 3.51 | P8: 27.3 | Q8: 20.5 | R8: 27.9
A9: Netflix | B9: NFLX | C9: Global subscription video streaming | D9: USD | E9: 45183 | F9: 51219 | G9: 56985 | H9: =F9/E9-1 -> 0.13359007 | I9: =G9/F9-1 -> 0.11257541 | J9: 17055 | K9: 20014 | L9: =J9/F9 -> 0.3329819 | M9: =K9/G9 -> 0.35121523 | N9: 5.72 | O9: 5.08 | P9: 17.2 | Q9: 14.5 | R9: 18.2
A10: Warner Music Group | B10: WMG | C10: Recorded music / publishing rights owner | D10: USD | E10: 6707 | F10: 7334 | G10: 7763 | H10: =F10/E10-1 -> 0.093484419 | I10: =G10/F10-1 -> 0.058494682 | J10: 1734 | K10: 1899 | L10: =J10/F10 -> 0.23643305 | M10: =K10/G10 -> 0.24462192 | N10: 2.58 | O10: 2.39 | P10: 10.9 | Q10: 9.77 | R10: 16.4
A11: Universal Music Group | B11: UMG | C11: Recorded music / publishing rights owner | D11: EUR | E11: 12507 | F11: 13426 | G11: 14372 | H11: =F11/E11-1 -> 0.073478852 | I11: =G11/F11-1 -> 0.070460301 | J11: 2797 | K11: 3054 | L11: =J11/F11 -> 0.20832713 | M11: =K11/G11 -> 0.21249652 | N11: 2.26 | O11: 2.08 | P11: 10.8 | Q11: 9.71 | R11: 15
A12: Tencent Music | B12: TME | C12: China music streaming / social entertainment | D12: RMB | E12: 32902 | F12: 35360 | G12: 38319 | H12: =F12/E12-1 -> 0.074706705 | I12: =G12/F12-1 -> 0.083682127 | J12: 11685 | K12: 12580 | L12: =J12/F12 -> 0.33045814 | M12: =K12/G12 -> 0.32829667 | N12: 1.64 | O12: 1.35 | P12: 4.92 | Q12: 3.99 | R12: 9.08
A13: Sirius XM | B13: SIRI | C13: Subscription audio / satellite radio | D13: USD | E13: 8558 | F13: 8590 | G13: 8712 | H13: =F13/E13-1 -> 0.0037391914 | I13: =G13/F13-1 -> 0.014202561 | J13: 2643 | K13: 2636 | L13: =J13/F13 -> 0.30768335 | M13: =K13/G13 -> 0.30257117 | N13: 2.11 | O13: 2.1 | P13: 6.8 | Q13: 6.96 | R13: 8.72
A15: Median (ex-SPOT) | H15: =MEDIAN(H9:H13) -> 0.074706705 | I15: =MEDIAN(I9:I13) -> 0.070460301 | L15: =MEDIAN(L9:L13) -> 0.30768335 | M15: =MEDIAN(M9:M13) -> 0.30257117 | N15: =MEDIAN(N9:N13) -> 2.26 | O15: =MEDIAN(O9:O13) -> 2.1 | P15: =MEDIAN(P9:P13) -> 10.8 | Q15: =MEDIAN(Q9:Q13) -> 9.71 | R15: =MEDIAN(R9:R13) -> 15
A16: Average (ex-SPOT) | H16: =AVERAGE(H9:H13) -> 0.075799847 | I16: =AVERAGE(I9:I13) -> 0.067883016 | L16: =AVERAGE(L9:L13) -> 0.28317672 | M16: =AVERAGE(M9:M13) -> 0.2878403 | N16: =AVERAGE(N9:N13) -> 2.862 | O16: =AVERAGE(O9:O13) -> 2.6 | P16: =AVERAGE(P9:P13) -> 10.124 | Q16: =AVERAGE(Q9:Q13) -> 8.986 | R16: =AVERAGE(R9:R13) -> 13.48
A19: Target Multiple Framework
A20: Metric | B20: Value
A21: SPOT current 2027E EV / EBITDA | B21: =Q8 -> 20.5
A22: 2027E ex-SPOT comp median | B22: =MEDIAN(Q9:Q13) -> 9.71
A23: 2027E music-rights median (WMG / UMG) | B23: =MEDIAN(Q10:Q11) -> 9.74
A24: 2027E Netflix EV / EBITDA | B24: =Q9 -> 14.5
A25: Selected terminal EV / EBITDA | B25: 12
A26: Premium / (discount) to ex-SPOT median | B26: =B25/B22-1 -> 0.23583934

Sheet Valuation
A1: Spotify Valuation & Cap Table
A3: Key Inputs | B3: Value | D3: Terminal Multiple Sensitivity
A4: Valuation date | B4: 2026-10-02 | D4: EV / EBITDA | E4: 9 | F4: 10 | G4: 11 | H4: 12 | I4: 13 | J4: 14.5
A5: Projection period end | B5: 2027-06-30 | D5: Implied $ / share | E5: =(($B$20*E$4)+$B$23+$B$24+$B$25)/$B$27*$B$7 -> 206.97127 | F5: =(($B$20*F$4)+$B$23+$B$24+$B$25)/$B$27*$B$7 -> 223.19825 | G5: =(($B$20*G$4)+$B$23+$B$24+$B$25)/$B$27*$B$7 -> 239.42524 | H5: =(($B$20*H$4)+$B$23+$B$24+$B$25)/$B$27*$B$7 -> 255.65223 | I5: =(($B$20*I$4)+$B$23+$B$24+$B$25)/$B$27*$B$7 -> 271.87921 | J5: =(($B$20*J$4)+$B$23+$B$24+$B$25)/$B$27*$B$7 -> 296.21969
A6: Current SPOT price ($) | B6: 472.89 | D6: Upside / (downside) | E6: =E5/$B$6-1 -> -0.56232682 | F6: =F5/$B$6-1 -> -0.52801232 | G6: =G5/$B$6-1 -> -0.49369782 | H6: =H5/$B$6-1 -> -0.45938331 | I6: =I5/$B$6-1 -> -0.42506881 | J6: =J5/$B$6-1 -> -0.37359705
A7: EUR / USD | B7: 1.1259
A8: Selected terminal EV / EBITDA | B8: ='Trading Comps'!B25 -> 12
D9: Current Market Cross-Check
D10: Current shares outstanding (mm) | E10: 205.58
A11: Terminal Operating Metrics | B11: Q2-27E LTM | D11: Current market cap ($bn) | E11: 97.22
A12: Revenue (€m) | B12: =Model!Y5 -> 20270.41 | D12: Current enterprise value ($bn) | E12: 89.77
A13: EBIT (€m) | B13: =Model!Y13 -> 2888.9705 | D13: Current 2027E EV / EBITDA | E13: 20.5
A14: D&A (€m) | B14: =Model!Y71+Model!Y72 -> 121.62246 | D14: Current 2027E P/E | E14: 27.9
A15: EBITDA (€m) | B15: =SUM(B13:B14) -> 3010.5929
A16: EBITDA margin | B16: =B15/B12 -> 0.14852156
A19: Valuation Bridge | B19: Value
A20: LTM EBITDA (€m) | B20: =B15 -> 3010.5929
A21: Terminal EV / EBITDA | B21: =B8 -> 12
A22: Implied enterprise value (€m) | B22: =B20*B21 -> 36127.115
A23: Cash & equivalents at Q2-27E (€m) | B23: =Model!S40 -> 7854.0456
A24: Short-term investments at Q2-27E (€m) | B24: =Model!S39 -> 3450
A25: Less: exchangeable notes (€m) | B25: =-(Model!S50+Model!S60) -> 0
A26: Implied equity value (€m) | B26: =SUM(B22:B25) -> 47431.161
A27: Diluted shares (mm) | B27: =Model!S24 -> 208.88824
A28: Implied value / share (€) | B28: =B26/B27 -> 227.06477
A30: Implied value / share ($) | B30: =B28*B7 -> 255.65223
A31: Downside vs. current price | B31: =B30/B6-1 -> -0.45938331

Sheet Assumptions
A1: Spotify Forecast Assumptions
A3: Driver | B3: Q3-2026E | C3: Q4-2026E | D3: Q1-2027E | E3: Q2-2027E
A4: Revenue (€m) | B4: 5000
A5: Revenue YoY growth | C5: 0.11 | D5: 0.1 | E5: 0.1
A6: Gross margin | B6: 0.329 | C6: 0.327 | D6: 0.328 | E6: 0.329
A7: Operating income (€m) | B7: 670
A8: Q3 R&D % of total Opex | B8: 0.42
A9: Q3 S&M % of total Opex | B9: 0.42
A10: Q3 G&A % of total Opex | B10: 0.16
A11: R&D % revenue | C11: 0.075 | D11: 0.076 | E11: 0.078
A12: S&M % revenue | C12: 0.08 | D12: 0.08 | E12: 0.08
A13: G&A % revenue | C13: 0.026 | D13: 0.026 | E13: 0.027
A14: Annualized interest yield on prior liquidity | B14: 0.035 | C14: 0.035 | D14: 0.035 | E14: 0.035
A15: Finance costs % revenue | B15: 0.0045 | C15: 0.0045 | D15: 0.0045 | E15: 0.0045
A16: Tax rate | B16: 0.24 | C16: 0.24 | D16: 0.24 | E16: 0.24
A17: Quarterly basic share change (mm) | B17: 0 | C17: 0 | D17: 0 | E17: 0
A18: Incremental diluted shares (mm) | B18: 3.1 | C18: 3.1 | D18: 3.1 | E18: 3.1
A19: D&A % revenue | B19: 0.005 | C19: 0.005 | D19: 0.005 | E19: 0.005
A20: Intangible amortization % revenue | B20: 0.001 | C20: 0.001 | D20: 0.001 | E20: 0.001
A21: SBC % revenue | B21: 0.016 | C21: 0.016 | D21: 0.016 | E21: 0.016
A22: Cash taxes / tax expense | B22: 0.85 | C22: 0.85 | D22: 0.85 | E22: 0.85
A23: Capex % revenue | B23: 0.0055 | C23: 0.0055 | D23: 0.0055 | E23: 0.0055
A24: Option exercise proceeds (€m) | B24: 30 | C24: 30 | D24: 30 | E24: 30
A25: Open-market buybacks (€m) | B25: 300 | C25: 300 | D25: 300 | E25: 300
... A37: Derivative liabilities (€m) | B37: 20 | C37: 20 | D37: 20 | E37: 20

Sheet Raw Numbers
A1: Spotify Reported Inputs (hardcodes; €m except per-share and shares)
A3: Annual Income Statement | B3: FY2023 | C3: FY2024 | D3: FY2025
A4: Revenue | B4: 13247 | C4: 15673 | D4: 17186
A5: Cost of revenue | B5: 9850 | C5: 10949 | D5: 11690
A6: Gross profit | B6: 3397 | C6: 4724 | D6: 5496
A7: R&D | B7: 1725 | C7: 1486 | D7: 1393
A8: Sales & marketing | B8: 1533 | C8: 1392 | D8: 1426
A9: G&A | B9: 585 | C9: 481 | D9: 479
A10: Total Opex | B10: 3843 | C10: 3359 | D10: 3298
A11: Operating income | B11: -446 | C11: 1365 | D11: 2198
A12: Finance income | B12: 161 | C12: 328 | D12: 292
A13: Finance costs | B13: -220 | C13: -352 | D13: -266
A14: Net finance | B14: -59 | C14: -24 | D14: 26
A15: Pretax income | B15: -505 | C15: 1341 | D15: 2224
... A21: Diluted WA shares | B21: 194.7323 | C21: 206.99037 | D21: 210.50917
A25: Reported Cash Flow (YTD / FY hardcodes)
A26: Line Item | B26: 2023 Q1 | C26: 2023 H1 | D26: 2023 9M | E26: 2023 FY | F26: 2024 Q1 | G26: 2024 H1 | H26: 2024 9M | I26: 2024 FY | J26: 2025 Q1 | K26: 2025 H1 | L26: 2025 9M | M26: 2025 FY | N26: 2026 Q1 | O26: 2026 H1
A27: Net income/(loss) | B27: -225 | C27: -527 | D27: -462 | E27: -532 | F27: 197 | G27: 471 | H27: 771 | I27: 1138 | J27: 225 | K27: 139 | L27: 1038 | M27: 2212 | N27: 721 | O27: 1266
A28: Depreciation - PP&E and ROU assets | B28: 31 | C28: 61 | D28: 87 | E28: 110 | F28: 22 | G28: 43 | H28: 64 | I28: 85 | J28: 20 | K28: 40 | L28: 59 | M28: 79 | N28: 20 | O28: 44
A29: Amortization of intangible assets | B29: 13 | C29: 27 | D29: 37 | E29: 48 | F29: 9 | G29: 18 | H29: 27 | I29: 36 | J29: 7 | K29: 13 | L29: 18 | M29: 23 | N29: 6 | O29: 11
A30: Impairment of real estate assets | B30: 0 | C30: 90 | D30: 90 | E30: 123 | F30: 4 | G30: 18 | H30: 18 | I30: 43 | J30: 2 | K30: 3 | L30: 8 | M30: 8 | N30: 4 | O30: 4
A31: Write-off of content assets | B31: 0 | C31: 30 | D31: 30 | E31: 29 | F31: 0 | G31: 0 | H31: 0 | I31: 0 | J31: 0 | K31: 0 | L31: 0 | M31: 0 | N31: 0 | O31: 0
A32: Share-based compensation expense | B32: 105 | C32: 202 | D32: 287 | E32: 321 | F32: 69 | G32: 150 | H32: 213 | I32: 267 | J32: 42 | K32: 115 | L32: 190 | M32: 247 | N32: 56 | O32: 142
A33: Finance income | B33: -27 | C33: -60 | D33: -115 | E33: -161 | F33: -59 | G33: -135 | H33: -201 | I33: -328 | J33: -71 | K33: -160 | L33: -422 | M33: -292 | N33: -248 | O33: -334
A34: Finance costs | B34: 77 | C34: 104 | D34: 118 | E34: 220 | F34: 53 | G34: 125 | H34: 247 | I34: 352 | J34: 252 | K34: 699 | L34: 716 | M34: 266 | N34: 26 | O34: 47
A35: Income tax expense/(benefit) | B35: 19 | C35: 80 | D35: 88 | E35: 27 | F35: -23 | G35: -27 | H35: 71 | I35: 203 | J35: 103 | K35: 237 | L35: 165 | M35: 12 | N35: 216 | O35: 391
A36: Other non-cash items | B36: -5 | C36: -3 | D36: -4 | E36: 1 | F36: 0 | G36: -1 | H36: -1 | I36: 2 | J36: 0 | K36: 8 | L36: 9 | M36: 10 | N36: -2 | O36: -1
A37: Change in trade receivables & other assets | B37: 118 | C37: 21 | D37: -48 | E37: -145 | F37: 80 | G37: 120 | H37: 116 | I37: 145 | J37: -4 | K37: -23 | L37: -49 | M37: -115 | N37: 91 | O37: 11
A38: Change in trade & other liabilities | B38: -57 | C38: 20 | D38: 82 | E38: 501 | F38: -171 | G38: -143 | H38: -57 | I38: 183 | J38: -90 | K38: 111 | L38: 211 | M38: 281 | N38: -94 | O38: 56
... A65: Supplemental: ROU assets recognized | B65: 15 | C65: 0 | D65: 22 | E65: 0 | F65: 13 | G65: 0 | H65: 0 | I65: 0 | J65: 18 | K65: 0 | L65: 0 | M65: 0 | N65: 0 | O65: 0
